<mujoco>

  <body name="peg" euler="0 0 0" pos="0 0 0.05">
    <inertial pos="0 0 0" mass="1"/>

    <!-- São as bases da ferramenta. Por enquanto não há necessidade de alterar -->
    <geom class="visual" type="cylinder" pos="0 0 0.01862" size="0.031 0.01862"/>
    <geom class="collision" type="cylinder" pos="0 0 0.01862" size="0.031 0.01862"/>
    <geom class="visual" type="cylinder" pos="0 0 0.042" size="0.038125 0.02541 0.00476"/>
    <geom class="collision" type="cylinder" pos="0 0 0.042" size="0.038125 0.02541 0.00476"/>
    

    <!-- Grippers -->

    <body name="Upper_Gr">
	    <geom name="Upper_Gripper" class="collision" type="box" pos="0 -0.004 0.1673" size="0.06 0.005 0.1" friction="0.3 0.009 0.0001"/>
	    <joint name="gripper" type="slide" pos="0 0 0" axis="0 1 0" range="0.006 0.009" limited="true"/>
    </body>

    <geom name="Lower_Gripper" class="collision" type="box" pos="0 0.015 0.1673" size="0.06 0.005 0.1" friction="0.3 0.005 0.0001"/>


    
    <!-- São as bolinhas vermelhas. Ainda não sei para o que serve -->
    <site name="peg_tip" pos="1 0 0.10902" euler="0 0 0" size="0.005, 0.005, 0.005"/>
    <site name="peg_ft_site" pos="1 0 0" euler="0 0 0" size="0.005, 0.005, 0.005"/>
	
  </body>
</mujoco>

			
	
