<mujoco>

  <body name="peg" euler="0 0 0" pos="0 0 0.05">
    <inertial pos="0 0 0" mass="1"/>

    <!-- São as bases da ferramenta. Por enquanto não há necessidade de alterar -->
    <geom class="visual" type="cylinder" pos="0 0 0.01862" size="0.031 0.01862"/>
    <geom class="collision" type="cylinder" pos="0 0 0.01862" size="0.031 0.01862"/>
    <geom class="visual" type="cylinder" pos="0 0 0.042" size="0.038125 0.02541 0.00476"/>
    <geom class="collision" type="cylinder" pos="0 0 0.042" size="0.038125 0.02541 0.00476"/>


    <!-- Grippers -->

    <body name="gripper_body" pos="0 0 0.06062">
      <geom name="gripper_geom" class="collision" type="box" pos="0 0 0.0375" size="0.017 0.026 0.0375" friction="0.8 0.009 0.0001" rgba="0.6 1 0.6 1" mass="0.6"/>

	    <body name="upper_finger_body">
		    <geom name="upper_finger_geom" class="collision" type="box" pos="0 0.006 0.115" size="0.035 0.005 0.04" friction="0.3 0.009 0.0001" rgba="1 0 0 1" mass="0.6"/>
		    <joint name="gripper_joint_upper" type="slide" pos="0 0 0" axis="0 1 0" range="-0.004 0.00" limited="true"/>
	    </body>

      <body name="lower_finger_body">
  	    <geom name="lower_finger" class="collision" type="box" pos="0 -0.011 0.115" size="0.035 0.005 0.04" friction="0.3 0.005 0.0001" mass="0.4"/>
        <!-- <joint name="gripper_joint_lower" type="slide" pos="0 0 0" axis="0 1 0" range="0 0.006" limited="true"/> -->
      </body>

    </body>



    <!-- São as bolinhas vermelhas. Ainda não sei para o que serve -->
    <site name="peg_tip" pos="0 0 0.185" euler="0 0 0" size="0.005, 0.005, 0.005"/>
    <site name="peg_ft_site" pos="0 0 0" euler="0 0 0" size="0.005, 0.005, 0.005"/>

  </body>
</mujoco>
